Workbook

Sheet Summary
A1: PlayClaw export | Ticket blast template library
A2: Source: playclaw_export (09-22-2026), n8n "Outreach Reply Logger | VHEA" pinned HubSpot marketing-email data. Counts below are live COUNTIF formulas over the Library tab.
A4: Category | B4: Templates | C4: Teammate-sender templates
A5: Game Ticketblast | B5: =COUNTIF(Library!$A$2:$A$2353,A5) -> 1091 | C5: =COUNTIFS(Library!$A$2:$A$2353,A5,Library!$J$2:$J$2353,"Yes") -> 11
A6: Freemium Tickets (team/state evergreen) | B6: =COUNTIF(Library!$A$2:$A$2353,A6) -> 497 | C6: =COUNTIFS(Library!$A$2:$A$2353,A6,Library!$J$2:$J$2353,"Yes") -> 0
A7: Follow-up | B7: =COUNTIF(Library!$A$2:$A$2353,A7) -> 253 | C7: =COUNTIFS(Library!$A$2:$A$2353,A7,Library!$J$2:$J$2353,"Yes") -> 2
A8: Template (master) | B8: =COUNTIF(Library!$A$2:$A$2353,A8) -> 236 | C8: =COUNTIFS(Library!$A$2:$A$2353,A8,Library!$J$2:$J$2353,"Yes") -> 0
A9: Playoff Blast | B9: =COUNTIF(Library!$A$2:$A$2353,A9) -> 83 | C9: =COUNTIFS(Library!$A$2:$A$2353,A9,Library!$J$2:$J$2353,"Yes") -> 0
A10: Suite Blast | B10: =COUNTIF(Library!$A$2:$A$2353,A10) -> 73 | C10: =COUNTIFS(Library!$A$2:$A$2353,A10,Library!$J$2:$J$2353,"Yes") -> 21
A11: Other / uncategorized | B11: =COUNTIF(Library!$A$2:$A$2353,A11) -> 28 | C11: =COUNTIFS(Library!$A$2:$A$2353,A11,Library!$J$2:$J$2353,"Yes") -> 10
A12: Premium (Club/VIP) Blast | B12: =COUNTIF(Library!$A$2:$A$2353,A12) -> 22 | C12: =COUNTIFS(Library!$A$2:$A$2353,A12,Library!$J$2:$J$2353,"Yes") -> 1
A13: Lower 100s Blast | B13: =COUNTIF(Library!$A$2:$A$2353,A13) -> 21 | C13: =COUNTIFS(Library!$A$2:$A$2353,A13,Library!$J$2:$J$2353,"Yes") -> 0
A14: Demo / meeting | B14: =COUNTIF(Library!$A$2:$A$2353,A14) -> 19 | C14: =COUNTIFS(Library!$A$2:$A$2353,A14,Library!$J$2:$J$2353,"Yes") -> 1
A15: Other Blast | B15: =COUNTIF(Library!$A$2:$A$2353,A15) -> 13 | C15: =COUNTIFS(Library!$A$2:$A$2353,A15,Library!$J$2:$J$2353,"Yes") -> 3
A16: Event / tryout / survey (NYC Basketball legacy) | B16: =COUNTIF(Library!$A$2:$A$2353,A16) -> 8 | C16: =COUNTIFS(Library!$A$2:$A$2353,A16,Library!$J$2:$J$2353,"Yes") -> 8
... A19: Support / transactional | B19: =COUNTIF(Library!$A$2:$A$2353,A19) -> 2 | C19: =COUNTIFS(Library!$A$2:$A$2353,A19,Library!$J$2:$J$2353,"Yes") -> 2
A20: Total | B20: =SUM(B5:B19) -> 2352 | C20: =SUM(C5:C19) -> 59

Sheet Library
A1: Category | B1: Template name | C1: Subject | D1: Sender | E1: Reply-to | F1: Publish date | G1: HubSpot campaign | H1: Source | I1: HubSpot asset ID | J1: Teammate sender (non-Josh) | K1: Mentions Teammate AI | L1: Landing pages | M1: Body (plain text)
A2: Lower 100s Blast | B2: 3/5 Blackhawks @ Mammoth Lower 100s Blast | C2: Invitation to Utah Mammoth Lower 100s Seats | D2: Josh Marcus | E2: josh.marcus@callplaybook.com | F2: 2026-03-05 | G2: Cole Tickets | H2: HubSpot marketing email (Cole Tickets campaign) | I2: 208780891792 | J2: No | K2: No | L2: https://www.callplaybook.com/ | M2: Good morning, My name is Josh Marcus, CEO/Co-Founder of Playbook [https://www.callplaybook.com/]. We wanted to personally invite you to lower 100s seats for the Blackhawks @ Mammoth game on March 12th, including premium seating as thank you for taking a demo of our software Playbook provides tools designed to automate the day-to-day processes of sports organizations, and help business owners save time normally spent completing administrative tasks. If that makes sense for you we would be delighted to connect and have you out for a great game! Are you free to connect tomorrow or sometime next week? Best, Josh Marcus CEO - Playbook Sports
A3: Suite Blast | B3: 3/5 Mavs @ Grizzlies Shared Suite Invitation | C3: Invitation to Memphis Grizzlies Suite | D3: Josh Marcus | E3: josh.marcus@callplaybook.com | F3: 2026-03-05 | G3: Cole Tickets | H3: HubSpot marketing email (Cole Tickets campaign) | I3: 208780874625 | J3: No | K3: No | L3: https://www.callplaybook.com/ | M3: Good morning, My name is Josh Marcus, CEO/Co-Founder of Playbook [https://www.callplaybook.com/]. We wanted to personally invite you to a luxury suite, including food and beverage, for the Grizzlies @ Grizzlies game on March 12th that we are hosting for out top potential youth sports organizations and facilities clients in part of a thank you for taking a demo of the software Playbook provides tools designed to automate the day-to-day processes of sports organizations, and help business owners save time normally spent completing administrative tasks. If that makes sense for you we would be delighted to connect and have you out for a great game! Are you free to connect tomorrow or sometime next week? Best, Josh Marcus CEO - Playbook Sports
A4: Game Ticketblast | B4: 3/5 Iowa @ Nebraska Ticketblast | C4: Quick Call for Iowa vs. Nebraska Tickets? | D4: Josh Marcus | E4: josh.marcus@callplaybook.com | F4: 2026-03-05 | G4: Cole Tickets | H4: HubSpot marketing email (Cole Tickets campaign) | I4: 208780873489 | J4: No | K4: No | L4: https://www.callplaybook.com/ | M4: Good morning, My name is Josh Marcus, CEO/Co-Founder of Playbook [https://www.callplaybook.com/]. We provide tools designed to automate the day-to-day processes of sports organizations, and help business owners save time normally spent completing administrative tasks. We also have a couple extra tickets for the Knicks @ Nuggets game on March 6th and I'd be happy to send a couple over as a gesture of appreciation for your time if you're interested in taking a demo of our platform. Are you free to connect later today or sometime this week? Best, Josh Marcus CEO - Playbook Sports
A5: Game Ticketblast | B5: 3/5 Lakers @ Rockets Ticketblast | C5: Quick Call for Lakers vs. Rockets Tickets? | D5: Josh Marcus | E5: josh.marcus@callplaybook.com | F5: 2026-03-05 | G5: Cole Tickets | H5: HubSpot marketing email (Cole Tickets campaign) | I5: 208780874513 | J5: No | K5: No | L5: https://www.callplaybook.com/ | M5: Good morning, My name is Josh Marcus, CEO/Co-Founder of Playbook [https://www.callplaybook.com/]. We provide tools designed to automate the day-to-day processes of sports organizations, and help business owners save time normally spent completing administrative tasks. We also have a couple extra tickets for the Lakers @ Rockets game on March 16th and I'd be happy to send a couple over as a gesture of appreciation for your time if you're interested in taking a demo of our platform. Are you free to connect tomorrow or sometime next week? Best, Josh Marcus CEO - Playbook Sports
A6: Game Ticketblast | B6: 3/5 Maple Leafs @ Canadiens Ticketblast | C6: Quick Call for Maple Leafs vs. Canadiens Tickets? | D6: Josh Marcus | E6: josh.marcus@callplaybook.com | F6: 2026-03-05 | G6: Cole Tickets | H6: HubSpot marketing email (Cole Tickets campaign) | I6: 208773202224 | J6: No | K6: No | L6: https://www.callplaybook.com/ | M6: Good morning, My name is Josh Marcus, CEO/Co-Founder of Playbook [https://www.callplaybook.com/]. We provide tools designed to automate the day-to-day processes of sports organizations, and help business owners save time normally spent completing administrative tasks. We also have a couple extra tickets for the Maple Leafs @ Canadiens game on March 10th and I'd be happy to send a couple over as a gesture of appreciation for your time if you're interested in taking a demo of our platform. Are you free to connect tomorrow or sometime next week? Best, Josh Marcus CEO - Playbook Sports
A7: Glass Seats Blast | B7: 3/5 Predators @ Canucks Glass Seats Ticketblast | C7: Quick Call for Vancouver Canucks Glass Seats? | D7: Josh Marcus | E7: josh.marcus@callplaybook.com | F7: 2026-03-05 | G7: Cole Tickets | H7: HubSpot marketing email (Cole Tickets campaign) | I7: 208780891716 | J7: No | K7: No | L7: https://www.callplaybook.com/ | M7: Good morning, My name is Josh Marcus, CEO/Co-Founder of Playbook [https://www.callplaybook.com/]. We provide tools designed to automate the day-to-day processes of sports organizations, and help business owners save time normally spent completing administrative tasks. We also have a couple Glass Seats for the Predators @ Canucks game on March 12th and I'd be happy to send a couple over as a gesture of appreciation for your time if you're interested in taking a demo of our platform. Are you free to connect tomorrow or sometime next week? Best, Josh Marcus CEO - Playbook Sports
A8: Suite Blast | B8: 3/5 Zaidman Capitals (Clone) | C8: VIP Suite Invite at Capitals Game | D8: Jake Zaidman | E8: jzaidman@callplaybook.com | F8: 2026-03-05 | G8: Cole Tickets | H8: HubSpot marketing email (Cole Tickets campaign) | I8: 208788212371 | J8: Yes | K8: No | M8: Good afternoon, My name is Jake Zaidman and I am on the partnerships team at Playbook Sports. I wanted to send over an email to extend an invitation to a VIP suite event my company is hosting on March 31st, during a Washington Capitals game for Sports Academy & Facility owners. Drinks are on us! We would love to have you out if you're around! If you're interested, let me know when I can give you a call, or just ring me directly at my cell: 551-236-2814. Best, Jake Playbook Sports
A9: Suite Blast | B9: 3/5 Grizzlies @ 76ers Shared Suite Invitation | C9: Invitation to 76ers Suite | D9: Josh Marcus | E9: josh.marcus@callplaybook.com | F9: 2026-03-05 | G9: Cole Tickets | H9: HubSpot marketing email (Cole Tickets campaign) | I9: 208774695982 | J9: No | K9: No | L9: https://www.callplaybook.com/ | M9: Good morning, My name is Josh Marcus, CEO/Co-Founder of Playbook [https://www.callplaybook.com/]. We wanted to personally invite you to a luxury suite, including food and beverage, for the Grizzlies @ 76ers game on March 10th that we are hosting for out top potential youth sports organizations and facilities clients in part of a thank you for taking a demo of the software Playbook provides tools designed to automate the day-to-day processes of sports organizations, and help business owners save time normally spent completing administrative tasks. If that makes sense for you we would be delighted to connect and have you out for a great game! Are you free to connect tomorrow or sometime next week? Best, Josh Marcus CEO - Playbook Sports
A10: Suite Blast | B10: 3/5 Wizards @ Pelicans Shared Suite Invitation | C10: Invitation to Pelicans Suite | D10: Josh Marcus | E10: josh.marcus@callplaybook.com | F10: 2026-03-05 | G10: Cole Tickets | H10: HubSpot marketing email (Cole Tickets campaign) | I10: 208770538255 | J10: No | K10: No | L10: https://www.callplaybook.com/ | M10: Good morning, My name is Josh Marcus, CEO/Co-Founder of Playbook [https://www.callplaybook.com/]. We wanted to personally invite you to a luxury suite for the Wizards @ Pelicans game on March 8th that we are hosting for out top potential youth sports organizations and facilities clients in part of a thank you for taking a demo of the software Playbook provides tools designed to automate the day-to-day processes of sports organizations, and help business owners save time normally spent completing administrative tasks. If that makes sense for you we would be delighted to connect and have you out for a great game! Are you free to connect tomorrow or sometime next week? Best, Josh Marcus CEO - Playbook Sports
A11: Glass Seats Blast | B11: 3/5 Islanders @ Senators Glass Seats Ticketblast | C11: Quick Call for Ottawa Senators Glass Seats? | D11: Josh Marcus | E11: josh.marcus@callplaybook.com | F11: 2026-03-05 | G11: Cole Tickets | H11: HubSpot marketing email (Cole Tickets campaign) | I11: 208770537237 | J11: No | K11: No | L11: https://www.callplaybook.com/ | M11: Good morning, My name is Josh Marcus, CEO/Co-Founder of Playbook [https://www.callplaybook.com/]. We provide tools designed to automate the day-to-day processes of sports organizations, and help business owners save time normally spent completing administrative tasks. We also have a couple Glass Seats for the Islanders @ Senators game on March 19th and I'd be happy to send a couple over as a gesture of appreciation for your time if you're interested in taking a demo of our platform. Are you free to connect tomorrow or sometime next week? Best, Josh Marcus CEO - Playbook Sports
A12: Suite Blast | B12: 3/5 Zaidman Capitals (Clone) | C12: VIP Suite Invite at Capitals Game | D12: Jake Zaidman | E12: jzaidman@callplaybook.com | F12: 2026-03-05 | G12: Cole Tickets | H12: HubSpot marketing email (live API page) | I12: 208788212371 | J12: Yes | K12: No | M12: Good afternoon, My name is Jake Zaidman and I am on the partnerships team at Playbook Sports. I wanted to send over an email to extend an invitation to a VIP suite event my company is hosting on March 31st, during a Washington Capitals game for Sports Academy & Facility owners. Drinks are on us! We would love to have you out if you're around! If you're interested, let me know when I can give you a call, or just ring me directly at my cell: 551-236-2814. Best, Jake Playbook Sports
A13: Game Ticketblast | B13: 3/5 Lakers @ Rockets Ticketblast | C13: Quick Call for Lakers vs. Rockets Tickets? | D13: Josh Marcus | E13: josh.marcus@callplaybook.com | F13: 2026-03-05 | G13: Cole Tickets | H13: HubSpot marketing email (live API page) | I13: 208780874513 | J13: No | K13: No | L13: https://www.callplaybook.com/ | M13: Good morning, My name is Josh Marcus, CEO/Co-Founder of Playbook [https://www.callplaybook.com/]. We provide tools designed to automate the day-to-day processes of sports organizations, and help business owners save time normally spent completing administrative tasks. We also have a couple extra tickets for the Lakers @ Rockets game on March 16th and I'd be happy to send a couple over as a gesture of appreciation for your time if you're interested in taking a demo of our platform. Are you free to connect tomorrow or sometime next week? Best, Josh Marcus CEO - Playbook Sports
A14: Lower 100s Blast | B14: 3/5 Blackhawks @ Mammoth Lower 100s Blast | C14: Invitation to Utah Mammoth Lower 100s Seats | D14: Josh Marcus | E14: josh.marcus@callplaybook.com | F14: 2026-03-05 | G14: Cole Tickets | H14: HubSpot marketing email (live API page) | I14: 208780891792 | J14: No | K14: No | L14: https://www.callplaybook.com/ | M14: Good morning, My name is Josh Marcus, CEO/Co-Founder of Playbook [https://www.callplaybook.com/]. We wanted to personally invite you to lower 100s seats for the Blackhawks @ Mammoth game on March 12th, including premium seating as thank you for taking a demo of our software Playbook provides tools designed to automate the day-to-day processes of sports organizations, and help business owners save time normally spent completing administrative tasks. If that makes sense for you we would be delighted to connect and have you out for a great game! Are you free to connect tomorrow or sometime next week? Best, Josh Marcus CEO - Playbook Sports
A15: Glass Seats Blast | B15: 3/5 Predators @ Canucks Glass Seats Ticketblast | C15: Quick Call for Vancouver Canucks Glass Seats? | D15: Josh Marcus | E15: josh.marcus@callplaybook.com | F15: 2026-03-05 | G15: Cole Tickets | H15: HubSpot marketing email (live API page) | I15: 208780891716 | J15: No | K15: No | L15: https://www.callplaybook.com/ | M15: Good morning, My name is Josh Marcus, CEO/Co-Founder of Playbook [https://www.callplaybook.com/]. We provide tools designed to automate the day-to-day processes of sports organizations, and help business owners save time normally spent completing administrative tasks. We also have a couple Glass Seats for the Predators @ Canucks game on March 12th and I'd be happy to send a couple over as a gesture of appreciation for your time if you're interested in taking a demo of our platform. Are you free to connect tomorrow or sometime next week? Best, Josh Marcus CEO - Playbook Sports
A16: Suite Blast | B16: 3/5 Mavs @ Grizzlies Shared Suite Invitation | C16: Invitation to Memphis Grizzlies Suite | D16: Josh Marcus | E16: josh.marcus@callplaybook.com | F16: 2026-03-05 | G16: Cole Tickets | H16: HubSpot marketing email (live API page) | I16: 208780874625 | J16: No | K16: No | L16: https://www.callplaybook.com/ | M16: Good morning, My name is Josh Marcus, CEO/Co-Founder of Playbook [https://www.callplaybook.com/]. We wanted to personally invite you to a luxury suite, including food and beverage, for the Grizzlies @ Grizzlies game on March 12th that we are hosting for out top potential youth sports organizations and facilities clients in part of a thank you for taking a demo of the software Playbook provides tools designed to automate the day-to-day processes of sports organizations, and help business owners save time normally spent completing administrative tasks. If that makes sense for you we would be delighted to connect and have you out for a great game! Are you free to connect tomorrow or sometime next week? Best, Josh Marcus CEO - Playbook Sports
A17: Game Ticketblast | B17: 3/5 Iowa @ Nebraska Ticketblast | C17: Quick Call for Iowa vs. Nebraska Tickets? | D17: Josh Marcus | E17: josh.marcus@callplaybook.com | F17: 2026-03-05 | G17: Cole Tickets | H17: HubSpot marketing email (live API page) | I17: 208780873489 | J17: No | K17: No | L17: https://www.callplaybook.com/ | M17: Good morning, My name is Josh Marcus, CEO/Co-Founder of Playbook [https://www.callplaybook.com/]. We provide tools designed to automate the day-to-day processes of sports organizations, and help business owners save time normally spent completing administrative tasks. We also have a couple extra tickets for the Knicks @ Nuggets game on March 6th and I'd be happy to send a couple over as a gesture of appreciation for your time if you're interested in taking a demo of our platform. Are you free to connect later today or sometime this week? Best, Josh Marcus CEO - Playbook Sports
A18: Suite Blast | B18: 3/5 Wizards @ Pelicans Shared Suite Invitation | C18: Invitation to Pelicans Suite | D18: Josh Marcus | E18: josh.marcus@callplaybook.com | F18: 2026-03-05 | G18: Cole Tickets | H18: HubSpot marketing email (live API page) | I18: 208770538255 | J18: No | K18: No | L18: https://www.callplaybook.com/ | M18: Good morning, My name is Josh Marcus, CEO/Co-Founder of Playbook [https://www.callplaybook.com/]. We wanted to personally invite you to a luxury suite for the Wizards @ Pelicans game on March 8th that we are hosting for out top potential youth sports organizations and facilities clients in part of a thank you for taking a demo of the software Playbook provides tools designed to automate the day-to-day processes of sports organizations, and help business owners save time normally spent completing administrative tasks. If that makes sense for you we would be delighted to connect and have you out for a great game! Are you free to connect tomorrow or sometime next week? Best, Josh Marcus CEO - Playbook Sports
A19: Suite Blast | B19: 3/5 Grizzlies @ 76ers Shared Suite Invitation | C19: Invitation to 76ers Suite | D19: Josh Marcus | E19: josh.marcus@callplaybook.com | F19: 2026-03-05 | G19: Cole Tickets | H19: HubSpot marketing email (live API page) | I19: 208774695982 | J19: No | K19: No | L19: https://www.callplaybook.com/ | M19: Good morning, My name is Josh Marcus, CEO/Co-Founder of Playbook [https://www.callplaybook.com/]. We wanted to personally invite you to a luxury suite, including food and beverage, for the Grizzlies @ 76ers game on March 10th that we are hosting for out top potential youth sports organizations and facilities clients in part of a thank you for taking a demo of the software Playbook provides tools designed to automate the day-to-day processes of sports organizations, and help business owners save time normally spent completing administrative tasks. If that makes sense for you we would be delighted to connect and have you out for a great game! Are you free to connect tomorrow or sometime next week? Best, Josh Marcus CEO - Playbook Sports
A20: Game Ticketblast | B20: 3/5 Maple Leafs @ Canadiens Ticketblast | C20: Quick Call for Maple Leafs vs. Canadiens Tickets? | D20: Josh Marcus | E20: josh.marcus@callplaybook.com | F20: 2026-03-05 | G20: Cole Tickets | H20: HubSpot marketing email (live API page) | I20: 208773202224 | J20: No | K20: No | L20: https://www.callplaybook.com/ | M20: Good morning, My name is Josh Marcus, CEO/Co-Founder of Playbook [https://www.callplaybook.com/]. We provide tools designed to automate the day-to-day processes of sports organizations, and help business owners save time normally spent completing administrative tasks. We also have a couple extra tickets for the Maple Leafs @ Canadiens game on March 10th and I'd be happy to send a couple over as a gesture of appreciation for your time if you're interested in taking a demo of our platform. Are you free to connect tomorrow or sometime next week? Best, Josh Marcus CEO - Playbook Sports
A21: Glass Seats Blast | B21: 3/5 Islanders @ Senators Glass Seats Ticketblast | C21: Quick Call for Ottawa Senators Glass Seats? | D21: Josh Marcus | E21: josh.marcus@callplaybook.com | F21: 2026-03-05 | G21: Cole Tickets | H21: HubSpot marketing email (live API page) | I21: 208770537237 | J21: No | K21: No | L21: https://www.callplaybook.com/ | M21: Good morning, My name is Josh Marcus, CEO/Co-Founder of Playbook [https://www.callplaybook.com/]. We provide tools designed to automate the day-to-day processes of sports organizations, and help business owners save time normally spent completing administrative tasks. We also have a couple Glass Seats for the Islanders @ Senators game on March 19th and I'd be happy to send a couple over as a gesture of appreciation for your time if you're interested in taking a demo of our platform. Are you free to connect tomorrow or sometime next week? Best, Josh Marcus CEO - Playbook Sports
A22: Suite Blast | B22: 3/30 Rays @ Brewers Ticketblast | C22: VIP Suite Invite HOME OPENER - Rays @ Brewers | D22: Danny Coleman | E22: danny@callplaybook.com | F22: 2026-03-04 | G22: Cole Tickets | H22: HubSpot marketing email (Cole Tickets campaign) | I22: 208716383305 | J22: Yes | K22: No | M22: Hello, My name is Danny Coleman and I am on the partnerships team at Playbook Sports. I wanted to send over an email to extend an invitation to a VIP suite event my company is hosting on March 30, during a Milwaukee Brewers game for sports organization managers and owners. Tickets are on us! We would love to have you out if you're around. Please let me know if you're interested!. Best, Danny Partnerships - Playbook Sports
A23: Lower 100s Blast | B23: 3/4 76ers @ Hawks Lower 100s Blast | C23: Invitation to Atlanta Hawks Lower 100s Seats | D23: Josh Marcus | E23: josh.marcus@callplaybook.com | F23: 2026-03-04 | G23: Cole Tickets | H23: HubSpot marketing email (Cole Tickets campaign) | I23: 208709657517 | J23: No | K23: No | L23: https://www.callplaybook.com/ | M23: Good morning, My name is Josh Marcus, CEO/Co-Founder of Playbook [https://www.callplaybook.com/]. We wanted to personally invite you to lower 100s seats for the 76ers @ Hawks game on March 7th, including premium seating as thank you for taking a demo of our software Playbook provides tools designed to automate the day-to-day processes of sports organizations, and help business owners save time normally spent completing administrative tasks. If that makes sense for you we would be delighted to connect and have you out for a great game! Are you free to connect sometime today or later this week? Best, Josh Marcus CEO - Playbook Sports
A24: Game Ticketblast | B24: 3/4 Knicks @ Nuggets Ticketblast | C24: Quick Call for Knicks vs. Nuggets Tickets? | D24: Josh Marcus | E24: josh.marcus@callplaybook.com | F24: 2026-03-04 | G24: Cole Tickets | H24: HubSpot marketing email (Cole Tickets campaign) | I24: 208720925069 | J24: No | K24: No | L24: https://www.callplaybook.com/ | M24: Good morning, My name is Josh Marcus, CEO/Co-Founder of Playbook [https://www.callplaybook.com/]. We provide tools designed to automate the day-to-day processes of sports organizations, and help business owners save time normally spent completing administrative tasks. We also have a couple extra tickets for the Knicks @ Nuggets game on March 6th and I'd be happy to send a couple over as a gesture of appreciation for your time if you're interested in taking a demo of our platform. Are you free to connect later today or sometime this week? Best, Josh Marcus CEO - Playbook Sports
A25: Game Ticketblast | B25: 3/4 Oilers @ Golden Knights Ticketblast | C25: Quick Call for Oilers vs. Golden Knights Tickets? | D25: Josh Marcus | E25: josh.marcus@callplaybook.com | F25: 2026-03-04 | G25: Cole Tickets | H25: HubSpot marketing email (Cole Tickets campaign) | I25: 208720677406 | J25: No | K25: No | L25: https://www.callplaybook.com/ | M25: Good morning, My name is Josh Marcus, CEO/Co-Founder of Playbook [https://www.callplaybook.com/]. We provide tools designed to automate the day-to-day processes of sports organizations, and help business owners save time normally spent completing administrative tasks. We also have a couple extra tickets for the Oilers @ Golden Knights game on March 8th and I'd be happy to send a couple over as a gesture of appreciation for your time if you're interested in taking a demo of our platform. Are you free to connect later today or sometime this week? Best, Josh Marcus CEO - Playbook Sports
A26: Lower 100s Blast | B26: 3/4 Magic @ Timberwolves Lower 100s Blast | C26: Invitation to Minnesota Timberwolves Lower 100s Seats | D26: Josh Marcus | E26: josh.marcus@callplaybook.com | F26: 2026-03-04 | G26: Cole Tickets | H26: HubSpot marketing email (Cole Tickets campaign) | I26: 208709657693 | J26: No | K26: No | L26: https://www.callplaybook.com/ | M26: Good morning, My name is Josh Marcus, CEO/Co-Founder of Playbook [https://www.callplaybook.com/]. We wanted to personally invite you to lower 100s seats for the Magic @ Timberwolves game on March 7th, including premium seating as thank you for taking a demo of our software Playbook provides tools designed to automate the day-to-day processes of sports organizations, and help business owners save time normally spent completing administrative tasks. If that makes sense for you we would be delighted to connect and have you out for a great game! Are you free to connect sometime today or later this week? Best, Josh Marcus CEO - Playbook Sports
A27: Game Ticketblast | B27: 3/4 Canucks @ Blackhawks Ticketblast | C27: Quick Call for Chicago Blackhawks Tickets? | D27: Josh Marcus | E27: josh.marcus@callplaybook.com | F27: 2026-03-04 | G27: Cole Tickets | H27: HubSpot marketing email (Cole Tickets campaign) | I27: 208709657762 | J27: No | K27: No | L27: https://www.callplaybook.com/ | M27: Good morning, My name is Josh Marcus, CEO/Co-Founder of Playbook [https://www.callplaybook.com/]. We provide tools designed to automate the day-to-day processes of sports organizations, and help business owners save time normally spent completing administrative tasks. We also have a couple extra tickets for the Canucks @ Blackhawks game on March 6th and I'd be happy to send a couple over as a gesture of appreciation for your time if you're interested in taking a demo of our platform. Are you free to connect later today or sometime this week? Best, Josh Marcus CEO - Playbook Sports
A28: Game Ticketblast | B28: 3/4 Warriors @ Thunder Ticketblast | C28: Quick Call for Warriors vs. Thunder Tickets? | D28: Josh Marcus | E28: josh.marcus@callplaybook.com | F28: 2026-03-04 | G28: Cole Tickets | H28: HubSpot marketing email (Cole Tickets campaign) | I28: 208720618398 | J28: No | K28: No | L28: https://www.callplaybook.com/ | M28: Good morning, My name is Josh Marcus, CEO/Co-Founder of Playbook [https://www.callplaybook.com/]. We provide tools designed to automate the day-to-day processes of sports organizations, and help business owners save time normally spent completing administrative tasks. We also have a couple extra tickets for the Warriors @ Thunder game on March 7th and I'd be happy to send a couple over as a gesture of appreciation for your time if you're interested in taking a demo of our platform. Are you free to connect later today or sometime this week? Best, Josh Marcus CEO - Playbook Sports
A29: Game Ticketblast | B29: 3/4 Knicks @ Nuggets Ticketblast | C29: Quick Call for Knicks vs. Nuggets Tickets? | D29: Josh Marcus | E29: josh.marcus@callplaybook.com | F29: 2026-03-04 | G29: Cole Tickets | H29: HubSpot marketing email (live API page) | I29: 208720925069 | J29: No | K29: No | L29: https://www.callplaybook.com/ | M29: Good morning, My name is Josh Marcus, CEO/Co-Founder of Playbook [https://www.callplaybook.com/]. We provide tools designed to automate the day-to-day processes of sports organizations, and help business owners save time normally spent completing administrative tasks. We also have a couple extra tickets for the Knicks @ Nuggets game on March 6th and I'd be happy to send a couple over as a gesture of appreciation for your time if you're interested in taking a demo of our platform. Are you free to connect later today or sometime this week? Best, Josh Marcus CEO - Playbook Sports
A30: Game Ticketblast | B30: 3/4 Warriors @ Thunder Ticketblast | C30: Quick Call for Warriors vs. Thunder Tickets? | D30: Josh Marcus | E30: josh.marcus@callplaybook.com | F30: 2026-03-04 | G30: Cole Tickets | H30: HubSpot marketing email (live API page) | I30: 208720618398 | J30: No | K30: No | L30: https://www.callplaybook.com/ | M30: Good morning, My name is Josh Marcus, CEO/Co-Founder of Playbook [https://www.callplaybook.com/]. We provide tools designed to automate the day-to-day processes of sports organizations, and help business owners save time normally spent completing administrative tasks. We also have a couple extra tickets for the Warriors @ Thunder game on March 7th and I'd be happy to send a couple over as a gesture of appreciation for your time if you're interested in taking a demo of our platform. Are you free to connect later today or sometime this week? Best, Josh Marcus CEO - Playbook Sports
A31: Game Ticketblast | B31: 3/4 Oilers @ Golden Knights Ticketblast | C31: Quick Call for Oilers vs. Golden Knights Tickets? | D31: Josh Marcus | E31: josh.marcus@callplaybook.com | F31: 2026-03-04 | G31: Cole Tickets | H31: HubSpot marketing email (live API page) | I31: 208720677406 | J31: No | K31: No | L31: https://www.callplaybook.com/ | M31: Good morning, My name is Josh Marcus, CEO/Co-Founder of Playbook [https://www.callplaybook.com/]. We provide tools designed to automate the day-to-day processes of sports organizations, and help business owners save time normally spent completing administrative tasks. We also have a couple extra tickets for the Oilers @ Golden Knights game on March 8th and I'd be happy to send a couple over as a gesture of appreciation for your time if you're interested in taking a demo of our platform. Are you free to connect later today or sometime this week? Best, Josh Marcus CEO - Playbook Sports
A32: Freemium Tickets (team/state evergreen) | B32: Columbus Freemium Tickets Email (BDA Suite Blast) | C32: Columbus Pro Sports Tickets from Playbook Sports | D32: Josh Marcus | E32: jmarcus@callplaybook.com | F32: 2026-03-04 | G32: BDA Suite Blast | H32: HubSpot marketing email (live API page) | I32: 208716075633 | J32: No | K32: No | L32: https://www.callplaybook.com/columbus-ticket-registration | https://www.callplaybook.com/get-started | M32: Hi, My name is Josh Marcus and I am the CEO and Founder of Playbook Sports [https://www.callplaybook.com/get-started], an all-in-one sports management software solution designed for ease of use and simplifying processes. To the start the year off with some energy, we're donating sports tickets to leaders in Columbus. I just reached out via text but wanted to follow up here and say I have Columbus Crew, Columbus Blue Jackets and Ohio State Buckeyes Men's Basketball tickets for games this season, at home, that I would like to donate to you for being an awesome leader in sports. Feel free to pick one of the form links [https://www.callplaybook.com/columbus-ticket-registration] below or just reply to this email with which team you would like to claim tickets for. Playbook will follow up and confirm your reservation. 1. Columbus Crew [https://www.callplaybook.com/columbus-ticket-registration] 2. Columbus Blue Jackets [https://www.callplaybook.com/columbus-ticket-registration] 3. Ohio State Buckeyes Men's Basketball [https://www.callplaybook.com/columbus-ticket-registration] We hope to connect soon and see you at a game! Sincerely, Josh We are offering these tickets in tandem with a free software demo over Zoom where you will learn a bit about how we help organizations like yours beyond just donating awesome sports tickets.
A33: Freemium Tickets (team/state evergreen) | B33: WV Freemium Ticket View 7/8 (BDA Suite Blast) | C33: Would you like to attend a Pro Sports Game??? | D33: Josh Marcus | E33: jmarcus@callplaybook.com | F33: 2026-03-04 | G33: BDA Suite Blast | H33: HubSpot marketing email (live API page) | I33: 208720175894 | J33: No | K33: No | L33: https://www.callplaybook.com/features | M33: Hi, I am Josh Marcus, Founder / CEO of Playbook Sports [https://www.callplaybook.com/features], a SAAS tool designed to automate all day to day processes for sports organizations. I came across the {{ company.name }} website and had to commend you for your contribution to your community. I was hoping I could link with you over a quick Zoom call, learn more about your organization and your future endeavors. I can also show you how Playbook Software has been working with other organizations to help them save admin time, and generate additional signups for your programs! I would love to throw in free MLB tickets to the Nationals, Guardians and the Phillies. Let me know if you have a time that works conveniently for you in the coming weeks and we'd be thrilled to speak with you. Have a good and I look forward to chatting with you further. Thanks, Josh Marcus CEO - Playbook Sports
A34: Game Ticketblast | B34: Enterprise Ticket Marketing Email May 12 (BDA Suite Blast) | C34: Would you like to attend a Pro Sports Game??? | D34: Josh Marcus | E34: jmarcus@callplaybook.com | F34: 2026-03-04 | G34: BDA Suite Blast | H34: HubSpot marketing email (live API page) | I34: 208716094056 | J34: No | K34: No | L34: https://www.callplaybook.com/features | M34: Hi, I am Josh Marcus, Founder / CEO of Playbook Sports [https://www.callplaybook.com/features], a SAAS tool designed to automate all day to day processes for sports organization. I came across the {{ company.name }} website and had to commend you for your contribution to your community. I was hoping I could link with you over a quick zoom call, learn more about your organization and show you our software. We'd love to get your feedback on our product and gain some perspective from you. I am happy to throw in free tickets to an MLB or MLS for you to attend as well. Let me know if you have a time that works conveniently for you in the coming week and I will be thrilled to speak with you. Have a super weekend and I look forward to chatting with you further. Thanks, Josh Marcus Playbook Sports
... A41: Freemium Tickets (team/state evergreen) | B41: Georgia Freemium Ticket View 12/12 (BDA Suite Blast) | C41: Would you like to see a Hawks, Falcons or CBB game on Playbook? | D41: Josh Marcus | E41: jmarcus@callplaybook.com | F41: 2026-03-04 | G41: BDA Suite Blast | H41: HubSpot marketing email (live API page) | I41: 208716075626 | J41: No | K41: No | L41: https://www.callplaybook.com/features | M41: Hi, I'm Josh Marcus, Founder and CEO of Playbook Sports [https://www.callplaybook.com/features]. We're a SAAS tool designed to automate the day to day processes for sports and multi-purpose organizations and help them save time spent doing repetitive administrative tasks. I came across the {{ company.name }} website and it seems like you guys are running a fantastic operation; I believe Playbook would be a great fit for you and your team. I was hoping to link with you over a quick Zoom call to learn more about your organization, and show you exactly how Playbook can be a fit to help save admin time and provide a more streamlined experience for your participants! I would love to throw in two free tickets to the following Hawks, Falcons or College Basketball games as well: - Hawks vs. Chicago Bulls (12/21) - Hawks vs. Detroit Pistons (12/23) - Falcons vs. Arizona Cardinals (01/01) - Alabama Basketball vs. Ole Miss (01/03) - Georgia Basketball vs. Auburn (01/12) Let me know if you'd have some time to chat in the coming weeks and we'd be thrilled to speak with you! Thanks, Josh Marcus CEO - Playbook Sports
A42: Game Ticketblast | B42: Minnesota Ticket Marketing Email May 16 (BDA Suite Blast) | C42: Would you like to attend a Pro Sports Game??? | D42: Josh Marcus | E42: jmarcus@callplaybook.com | F42: 2026-03-04 | H42: HubSpot marketing email (live API page) | I42: 208715415964 | J42: No | K42: No | L42: https://www.callplaybook.com/features | M42: Hi, I am Josh Marcus, Founder / CEO of Playbook Sports [https://www.callplaybook.com/features], a SAAS tool designed to automate all day to day processes for sports organization. I came across the {{ company.name }} website and had to commend you for your contribution to your community. I was hoping I could link with you over a quick zoom call, learn more about your organization and show you our software. We'd love to show you how Playbook Software can help you save admin time, and generate additional signups for your programs! I am happy to throw in free tickets to a Twins, Lynx or Minnesota United FC game for you to attend as well. Let me know if you have a time that works conveniently for you in the coming week and I will be thrilled to speak with you. Have a super weekend and I look forward to chatting with you further. Thanks, Josh Marcus Playbook Sports
A43: Freemium Tickets (team/state evergreen) | B43: Seattle non-specific Freemium Ticket View 8/22 (BDA Suite Blast) | C43: Would you like to attend a Seattle Sounders Game on Playbook? | D43: Josh Marcus | E43: jmarcus@callplaybook.com | F43: 2026-03-04 | G43: BDA Suite Blast | H43: HubSpot marketing email (live API page) | I43: 208720327056 | J43: No | K43: No | L43: https://www.callplaybook.com/features | M43: Hi, I'm Josh Marcus, Founder and CEO of Playbook Sports [https://www.callplaybook.com/features]. We're a SAAS tool designed to automate the day to day processes for sports and multi-purpose organizations and help them save time spent doing repetitive administrative tasks. I came across the {{ company.name }} website and it seems like you guys are running a fantastic operation; I believe Playbook would be a great fit for you and your team. I was hoping to link with you over a quick Zoom call to learn more about your organization, and show you exactly how Playbook can be a fit to help save admin time and provide a more streamlined experience for your participants as well! I would love to throw in free Mariners or Sounders FC tickets to one of the following games as well: - Mariners v. Braves (9/10) - Mariners v. Padres (9/14) - Mariners v. Rangers (9/27) - Sounders v. Houston Dynamo (9/4) - Sounders v. FC Cincinnati (9/27) - Sounders v. San Jose Earthquakes (10/9). Let me know if you'd have some time to chat in the coming weeks and we'd be thrilled to speak with you! Thanks, Josh Marcus CEO - Playbook Sports
A44: Freemium Tickets (team/state evergreen) | B44: Florida All Teams Freemium Tickets Email (BDA Suite Blast) | C44: Your Florida Pro Sports Tickets from Playbook Sports | D44: Josh Marcus | E44: jmarcus@callplaybook.com | F44: 2026-03-04 | G44: BDA Suite Blast | H44: HubSpot marketing email (live API page) | I44: 208719837589 | J44: No | K44: No | L44: https://www.callplaybook.com/florida-ticket-registration | https://www.callplaybook.com/get-started | M44: Hi, My name is Josh Marcus and I am the CEO and Founder of Playbook Sports [https://www.callplaybook.com/get-started], an all-in-one sports management software solution designed for ease of use and simplifying processes for you and your players. I'm looking to connect with awesome community leaders like you in Florida. To break the ice, I'm donating pro sports tickets and want you to take advantage of this offer. I have Heat, Magic, Lightning, and Panthers tickets for games this season at home (I also have tickets to the Rays, Marlins, Orlando City SC, and Inter Miami CF). If you are interested, all I ask is your time for a free software demo with Playbook, more info below. Feel free to pick one of the form links [https://www.callplaybook.com/florida-ticket-registration] below or just reply to this email with which team you would like to claim tickets for, Playbook will follow up and confirm your reservation. 1. Miami Heat [https://www.callplaybook.com/florida-ticket-registration] 2. Orlando Magic [https://www.callplaybook.com/florida-ticket-registration] 3. Tampa Bay Lightning [https://www.callplaybook.com/florida-ticket-registration] 4. Florida Panthers [https://www.callplaybook.com/florida-ticket-registration] 5. Rays/Marlins/Orlando City/Inter Miami Ticket Request [https://www.callplaybook.com/florida-ticket-registration] We hope to connect soon and see you at a game! Sincerely, Josh We are offering these tickets in tandem with a free software demo over Zoom where you will learn a bit about how we help organizations like yours beyond donating awesome sports tickets. In our demo, we will walk you through our relevant features, what it would look and feel like for you and your customers to use it, and show you how we stand out from other software providers. It's an awesome way to see what else is out there in sports tech even if you cannot make a software switch right now.
A45: Game Ticketblast | B45: Ohio Ticket Marketing Email 3/29 (BDA Suite Blast) | C45: Would you like to attend a Pro Sports Game??? | D45: Josh Marcus | E45: jmarcus@callplaybook.com | F45: 2026-03-04 | H45: HubSpot marketing email (live API page) | I45: 208718954898 | J45: No | K45: No | L45: https://www.callplaybook.com/features | M45: Hi, I am Josh Marcus, Founder / CEO of Playbook Sports [https://www.callplaybook.com/features], a SAAS tool designed designed to automate all day to day processes for sports organization. I came across the {{ company.name }} website and had to commend you for your contribution to your community. I was hoping I could link with you over a quick zoom call, learn more about your organization and show your our software. We'd love to get your feedback on our product and gain some perspective from you. I am happy to throw in free tickets to a pro sports game for you to attend as well. Let me know if you have a time that works conveniently for you in the coming week and I will be thrilled to speak with you. Have a super weekend and I look forward to chatting with you further. Thanks, Josh Marcus Playbook Sports
A46: Demo / meeting | B46: FedEx Sideline Space for Demo Email (Mindbody Leads) (BDA Suite Blast) | C46: Free Field Slots at FedEx Field, Playbook Sports Events Special | D46: Josh Marcus | E46: jmarcus@callplaybook.com | F46: 2026-03-04 | G46: BDA Suite Blast | H46: HubSpot marketing email (live API page) | I46: 208720175888 | J46: No | K46: No | L46: http://www.callplaybook.com/features | M46: Hello, I hope you are well. I am reaching out from Playbook Sports [http://www.callplaybook.com/features] because we have some field space available on the FedEx Field sideline and I think your program would be a great fit. I saw your organization while looking through local programs and think you would be able to run an awesome class, clinic, or training session with that hour of free field time. You can take advantage of the space for photos for your organization's social media and invite fans and family to come to watch. Are you interested in booking that field time at FedEx Field and a free software demo with Playbook? Sincerely, Josh I think we would be a great fit for you as a software partner too. Our software is built to streamline registration, member management, scheduling/staffing, financial reporting, and much more so that operating a community activities business is as easy as possible. For all organizations doing a stadium event with us, we provide a free demo of our software in a 20 or so minute, free, online meeting where we can compare what we offer to Mindbody.
...
